Workbook

Sheet COMP-SABERES
A1: Tecnología e Ingeniería I (1º Bachillerato) | C1: BLOQUES SABERES
C2: 1 | D2: 2 | E2: 3 | F2: 4 | G2: 5 | H2: 6 | I2: 7 | J2: 8
A3: COMPETENCIAS ESPECIFICAS | B3: 1 | C3: X | D3: X | E3: X | F3: X
B4: 2 | D4: X | J4: X
B5: 3 | C5: X | D5: X | E5: X | F5: X | H5: X | I5: X | J5: X
B6: 4 | C6: X | E6: X | F6: X | G6: X
B7: 5 | H7: X | I7: X
B8: 6 | C8: X | F8: X | J8: X

Sheet sit aprendizaje- competencias
D1: COMPETENCIAS ESPECÍFICAS CON SUS CRITERIOS DE EVALUACIÓN
D2: CE1 | J2: CE2 | N2: CE3 | Q2: CE4 | U2: CE5 | Z2: CE6
A3: EVALUACIONES | B3: SA | C3: Temporalización en semanas/sesiones/trimestre | D3: 1.1 | E3: 1.2 | F3: 1.3 | G3: 1.4 | H3: 1.5 | I3: 1.6 | J3: 2.1 | K3: 2.2 | L3: 2.3 | M3: 2.4 | N3: 3.1 | O3: 3.2 | P3: 3.3 | Q3: 4.1 | R3: 4.2 | S3: 4.3 | T3: 4.4 | U3: 5.1 | V3: 5.2 | W3: 5.3 | X3: 5.4 | Y3: 5.5 | Z3: 6.1 | AA3: 6.2 | AB3: 6.3 | AC3: 6.4
A4: 1 | B4: URBANLAB 1.0 - BLOQUE I | C4: 34 Sesiones | D4: X | E4: X | F4: X | G4: X | H4: X | I4: X | J4: X | K4: X | L4: X | M4: X | N4: X | O4: X | P4: X
A5: 2 | B5: URBANLAB 1.0 - BLOQUE II | C5: 34 Sesiones | D5: X | E5: X | F5: X | G5: X | I5: X | K5: X | N5: X | P5: X | Q5: X | T5: X | AC5: X
A6: 3 | B6: URBANLAB 1.0 - BLOQUE III | C6: 35 sesiones | D6: X | E6: X | F6: X | G6: X | I6: X | K6: X | N6: X | P6: X | R6: X | U6: X | V6: X | W6: X | X6: X | Y6: X | AB6: X
B7: URBANLAB 1.0 - BLOQUE IV | C7: 35 sesiones | D7: X | E7: X | F7: X | G7: X | H7: X | I7: X | K7: X | M7: X | N7: X | O7: X | P7: X | S7: X | Z7: X | AA7: X
B10: BLOQUE I | C10: Bloque 1: Proyecto de investigación y desarrollo.
C11: Bloque 2: Materiales y fabricación.
C12: Bloque 3: Sistemas mecánicos.
C13: Bloque 4: Sistemas eléctricos y electrónicos.
C14: Bloque 8: Tecnología sostenible.
B16: BLOQUE II | C16: Bloque 1: Proyecto de investigación y desarrollo.
C17: Bloque 3: Sistemas mecánicos.
C18: Bloque 5: Telecomunicaciones.
B20: BLOQUE III | C20: Bloque 4: Sistemas eléctricos y electrónicos.
C21: Bloque 6: Sistemas informáticos.
C22: Bloque 7: Automatización.
B24: BLOQUE IV | C24: Bloque 1: Proyecto de investigación y desarrollo.
C25: Bloque 8: Tecnología sostenible.

Sheet peso de las competencias
A3: COMPETENCIAS | B3: PORCENTAJE DE NOTA DE LA MATERIA | E3: CRITERIOS | F3: PORCENTAJE DE NOTA DE LA COMPETENCIA | G3: PORCENTAJE DE NOTA DEL CURSO
A4: CE1 | B4: =1/6 -> 0.16666667 | E4: 1.1 | F4: =1/6 -> 0.16666667 | G4: =F4*$B$4 -> 0.027777778
A5: CE2 | B5: =1/6 -> 0.16666667 | E5: 1.2 | F5: =1/6 -> 0.16666667 | G5: =F5*$B$4 -> 0.027777778
A6: CE3 | B6: =1/6 -> 0.16666667 | E6: 1.3 | F6: =1/6 -> 0.16666667 | G6: =F6*$B$4 -> 0.027777778
A7: CE4 | B7: =1/6 -> 0.16666667 | E7: 1.4 | F7: =1/6 -> 0.16666667 | G7: =F7*$B$4 -> 0.027777778
A8: CE5 | B8: =1/6 -> 0.16666667 | E8: 1.5 | F8: =1/6 -> 0.16666667 | G8: =F8*$B$4 -> 0.027777778
A9: CE6 | B9: =1/6 -> 0.16666667 | E9: 1.6 | F9: =1/6 -> 0.16666667 | G9: =F9*$B$4 -> 0.027777778
A10: TOTAL MATERIA (TECNO E ING.I) | B10: =SUM(B4:B9) -> 1 | E10: TOTAL CE1 | F10: =SUM(F4:F9) -> 1 | G10: =SUM(G4:G9) -> 0.16666667
E12: 2.1 | F12: =1/4 -> 0.25 | G12: =F12*$B$5 -> 0.041666667
E13: 2.2 | F13: =1/4 -> 0.25 | G13: =F13*$B$5 -> 0.041666667
E14: 2.3 | F14: =1/4 -> 0.25 | G14: =F14*$B$5 -> 0.041666667
E15: 2.4 | F15: =1/4 -> 0.25 | G15: =F15*$B$5 -> 0.041666667
E16: TOTAL CE2 | F16: =SUM(F12:F15) -> 1 | G16: =SUM(G12:G15) -> 0.16666667
E18: 3.1 | F18: =1/3 -> 0.33333333 | G18: =F18*$B$6 -> 0.055555556
E19: 3.2 | F19: =1/3 -> 0.33333333 | G19: =F19*$B$6 -> 0.055555556
E20: 3.3 | F20: =1/3 -> 0.33333333 | G20: =F20*$B$6 -> 0.055555556
E21: TOTAL CE3 | F21: =SUM(F18:F20) -> 1 | G21: =SUM(G18:G20) -> 0.16666667
E23: 4.1 | F23: =1/4 -> 0.25 | G23: =F23*$B$7 -> 0.041666667
E24: 4.2 | F24: =1/4 -> 0.25 | G24: =F24*$B$7 -> 0.041666667
E25: 4.3 | F25: =1/4 -> 0.25 | G25: =F25*$B$7 -> 0.041666667
E26: 4.4 | F26: =1/4 -> 0.25 | G26: =F26*$B$7 -> 0.041666667
E27: TOTAL CE4 | F27: =SUM(F23:F26) -> 1 | G27: =SUM(G23:G26) -> 0.16666667
E29: 5.1 | F29: =1/5 -> 0.2 | G29: =F29*$B$8 -> 0.033333333
E30: 5.2 | F30: =1/5 -> 0.2 | G30: =F30*$B$8 -> 0.033333333
E31: 5.3 | F31: =1/5 -> 0.2 | G31: =F31*$B$8 -> 0.033333333
E32: 5.4 | F32: =1/5 -> 0.2 | G32: =F32*$B$8 -> 0.033333333
E33: 5.5 | F33: =1/5 -> 0.2 | G33: =F33*$B$8 -> 0.033333333
E34: TOTAL CE5 | F34: =SUM(F29:F33) -> 1 | G34: =SUM(G29:Z33) -> 0.16666667
E36: 6.1 | F36: =1/4 -> 0.25 | G36: =F36*$B$9 -> 0.041666667
E37: 6.2 | F37: =1/4 -> 0.25 | G37: =F37*$B$9 -> 0.041666667
E38: 6.3 | F38: =1/4 -> 0.25 | G38: =F38*$B$9 -> 0.041666667
E39: 6.4 | F39: =1/4 -> 0.25 | G39: =F39*$B$9 -> 0.041666667
E40: TOTAL CE6 | F40: =SUM(F36:F39) -> 1 | G40: =SUM(G36:G39) -> 0.16666667

Sheet 1ªEV
A1: 1ª EVALUACIÓN
G5: DETALLE | R5: COMPETENCIAS | S5: PORCENTAJE DE NOTA DE LA MATERIA | T5: PONDERACIÓN 1ª TRIMESTRE | U5: % CONSEGUIDO 1º TRIMESTRE
A6: CRIT EVAL | B6: PONDERACIÓN DEL CURSO | C6: PROGRESO | D6: PONDERACIÓN 1ª TRIMESTRE | E6: CONSEGUIDO | F6: % CONSEGUIDO | G6: EVIDENCIA A | H6: EVIDENCIA B | I6: EVIDENCIA C | J6: EVIDENCIA D | K6: EVIDENCIA E | L6: EVIDENCIA F | M6: EVIDENCIA G | N6: EVIDENCIA H | O6: EVIDENCIA I | P6: EVIDENCIA J | R6: CE1 | S6: =1/6 -> 0.16666667 | T6: =D13 -> 0.048611111 | U6: =F13 -> 0.048611111
A7: 46023 | B7: ='peso de las competencias'!G4 -> 0.027777778 | C7: 0.25 | D7: =C7*B7 -> 0.0069444444 | E7: =IF($C7=0, 0, IFERROR(SUM($G7:$P7)/COUNT($G7:$P7), 0)) -> 10 | F7: =(E7/10)*D7 -> 0.0069444444 | G7: 10 | R7: CE2 | S7: =1/6 -> 0.16666667 | T7: =D21 -> 0.11458333 | U7: =F21 -> 0.11458333
A8: 46054 | B8: ='peso de las competencias'!G5 -> 0.027777778 | C8: 0.25 | D8: =C8*B8 -> 0.0069444444 | E8: =IF($C8=0, 0, IFERROR(SUM($G8:$P8)/COUNT($G8:$P8), 0)) -> 10 | F8: =(E8/10)*D8 -> 0.0069444444 | G8: 10 | H8: 10 | R8: CE3 | S8: =1/6 -> 0.16666667 | T8: =D28 -> 0.055555556 | U8: =F28 -> 0.055555556
A9: 46082 | B9: ='peso de las competencias'!G6 -> 0.027777778 | C9: 0.25 | D9: =C9*B9 -> 0.0069444444 | E9: =IF($C9=0, 0, IFERROR(SUM($G9:$P9)/COUNT($G9:$P9), 0)) -> 10 | F9: =(E9/10)*D9 -> 0.0069444444 | G9: 10 | R9: CE4 | S9: =1/6 -> 0.16666667 | T9: 0 | U9: 0
A10: 46113 | B10: ='peso de las competencias'!G7 -> 0.027777778 | C10: 0.25 | D10: =C10*B10 -> 0.0069444444 | E10: =IF($C10=0, 0, IFERROR(SUM($G10:$P10)/COUNT($G10:$P10), 0)) -> 10 | F10: =(E10/10)*D10 -> 0.0069444444 | G10: 10 | O10: 10 | R10: CE5 | S10: =1/6 -> 0.16666667 | T10: 0 | U10: 0
A11: 46143 | B11: ='peso de las competencias'!G8 -> 0.027777778 | C11: 0.5 | D11: =C11*B11 -> 0.013888889 | E11: =IF($C11=0, 0, IFERROR(SUM($G11:$P11)/COUNT($G11:$P11), 0)) -> 10 | F11: =(E11/10)*D11 -> 0.013888889 | G11: 10 | R11: CE6 | S11: =1/6 -> 0.16666667 | T11: 0 | U11: 0
A12: 46174 | B12: ='peso de las competencias'!G9 -> 0.027777778 | C12: 0.25 | D12: =C12*B12 -> 0.0069444444 | E12: =IF($C12=0, 0, IFERROR(SUM($G12:$P12)/COUNT($G12:$P12), 0)) -> 10 | F12: =(E12/10)*D12 -> 0.0069444444 | G12: 10 | N12: 10 | P12: 10 | R12: TOTAL | S12: =SUM(S6:S11) -> 1 | T12: =SUM(T6:T11) -> 0.21875 | U12: =SUM(U6:U11) -> 0.21875
A13: COMP ESP 1 | B13: =SUM(B7:B12) -> 0.16666667 | D13: =SUM(D7:D12) -> 0.048611111 | F13: =SUM(F7:F12) -> 0.048611111 | T13: NOTA 1º TRIMESTRE | U13: =IF(T12=0, 0, (U12/T12)*10) -> 10
T14: NOTA 1ª EVALUACIÓN | U14: =SUM(U13)/1 -> 10
G15: DETALLE
A16: CRIT EVAL | B16: PONDERACIÓN DEL CURSO | C16: PROGRESO | D16: PONDERACIÓN 1ª TRIMESTRE | E16: CONSEGUIDO | F16: % CONSEGUIDO | G16: EVIDENCIA A | H16: EVIDENCIA B | I16: EVIDENCIA C | J16: EVIDENCIA D | K16: EVIDENCIA E | L16: EVIDENCIA F | M16: EVIDENCIA G | N16: EVIDENCIA H | O16: EVIDENCIA I | P16: EVIDENCIA J
A17: 46024 | B17: ='peso de las competencias'!G12 -> 0.041666667 | C17: 1 | D17: =C17*B17 -> 0.041666667 | E17: =IF($C17=0, 0, IFERROR(SUM($G17:$P17)/COUNT($G17:$P17), 0)) -> 10 | F17: =(E17/10)*D17 -> 0.041666667 | G17: 10 | I17: 10
A18: 46055 | B18: ='peso de las competencias'!G13 -> 0.041666667 | C18: 0.25 | D18: =C18*B18 -> 0.010416667 | E18: =IF($C18=0, 0, IFERROR(SUM($G18:$P18)/COUNT($G18:$P18), 0)) -> 10 | F18: =(E18/10)*D18 -> 0.010416667 | G18: 10 | J18: 10 | K18: 10 | O18: 10
A19: 46083 | B19: ='peso de las competencias'!G14 -> 0.041666667 | C19: 1 | D19: =C19*B19 -> 0.041666667 | E19: =IF($C19=0, 0, IFERROR(SUM($G19:$P19)/COUNT($G19:$P19), 0)) -> 10 | F19: =(E19/10)*D19 -> 0.041666667 | G19: 10
A20: 46114 | B20: ='peso de las competencias'!G15 -> 0.041666667 | C20: 0.5 | D20: =C20*B20 -> 0.020833333 | E20: =IF($C20=0, 0, IFERROR(SUM($G20:$P20)/COUNT($G20:$P20), 0)) -> 10 | F20: =(E20/10)*D20 -> 0.020833333 | G20: 10
A21: COMP ESP 2 | B21: =SUM(B17:B20) -> 0.16666667 | D21: =SUM(D17:D20) -> 0.11458333 | F21: =SUM(F17:F20) -> 0.11458333
G23: DETALLE
A24: CRIT EVAL | B24: PONDERACIÓN DEL CURSO | C24: PROGRESO | D24: PONDERACIÓN 1ª TRIMESTRE | E24: CONSEGUIDO | F24: % CONSEGUIDO | G24: EVIDENCIA A | H24: EVIDENCIA B | I24: EVIDENCIA C | J24: EVIDENCIA D | K24: EVIDENCIA E | L24: EVIDENCIA F | M24: EVIDENCIA G | N24: EVIDENCIA H | O24: EVIDENCIA I | P24: EVIDENCIA J
A25: 46025 | B25: ='peso de las competencias'!G18 -> 0.055555556 | C25: 0.25 | D25: =C25*B25 -> 0.013888889 | E25: =IF($C25=0, 0, IFERROR(SUM($G25:$P25)/COUNT($G25:$P25), 0)) -> 10 | F25: =(E25/10)*D25 -> 0.013888889 | G25: 10 | M25: 10
A26: 46056 | B26: ='peso de las competencias'!G19 -> 0.055555556 | C26: 0.5 | D26: =C26*B26 -> 0.027777778 | E26: =IF($C26=0, 0, IFERROR(SUM($G26:$P26)/COUNT($G26:$P26), 0)) -> 10 | F26: =(E26/10)*D26 -> 0.027777778 | L26: 10
A27: 46084 | B27: ='peso de las competencias'!G20 -> 0.055555556 | C27: 0.25 | D27: =C27*B27 -> 0.013888889 | E27: =IF($C27=0, 0, IFERROR(SUM($G27:$P27)/COUNT($G27:$P27), 0)) -> 10 | F27: =(E27/10)*D27 -> 0.013888889 | G27: 10 | L27: 10
A28: COMP ESP 3 | B28: =SUM(B25:B27) -> 0.16666667 | D28: =SUM(D25:D27) -> 0.055555556 | F28: =SUM(F25:F27) -> 0.055555556 | R28: EVIDENCIAS | S28: TIPOS DE EVIDENCIAS | U28: CEv relacionados | V28: DESCRIPCIÓN
R29: A | S29: Memoria | T29: Apartado 1 (Portada y roles) | U29: 5.1.6 (Trabajo en equpo y roles) | V29: Portada, logo del equipo, componentes y elección de roles principales.
T30: Apartado 2 (Intro y análisis) | U30: 5.1.1 (Investigación) | V30: Informe donde el alumno analiza el conflicto urbano, investiga y propone una solución del reto y referencia las fuentes de información consultadas relacionándolas con su solución.
T31: Apartado 3 (Justificación estructural) | U31: 5.1.2 (Iteración) 5.2.1 (Materiales) 5.1.5 (Ciclo de vida) | V31: Explicación detallada de cómo ha evolucionado la idea, justificando los cambios realizados desde el boceto al diseño final. Justificación de los materiales elegidos y reflexión técnica sobre el impacto ecosocial del proyecto en el marco del ODS 11. Planificación de la mejora continua del producto desde su diseño virtual hasta su implantación final en el espacio público.
T32: Apartado 4 (Diseño Técnico) = | U32: 5.1.3 (Doc. técnica) | V32: Documentación visual mediante capturas del modelo 3D y esquemas que explican el funcionamiento del sistema.
T33: Apartado 5 (Planos CAD) | U33: 5.1.4 (Rep. Gráfica) | V33: Planos finales 2D exportados de LibreCAD. Deben cumplir con la normalización (vistas, escalas, acotación y simbología técnica).
T34: Apartado 6 (Proceso de fabricación) | U34: 5.2.2 (Fabricación) 5.2.3 (Nuevos materiales) 5.2.4 (Materiales inteligentes) | V34: Análisis sobre la sostenibilidad de nuevos materiales, su ciclo de vida y su impacto transformador en la sociedad, relacionando el prototipo con soluciones derivadas de la nanotecnología, biotecnología o materiales inteligentes. Documentación de los parámetros de laminado (relleno, capas, soportes) y fotos del proceso real.
T35: Apartado 7 (Presupuesto) | U35: 5.3.1 (Herr. Digitales) | V35: Uso de herramientas (hojas de cálculo) para estimar el coste económico del filamento y consumo energético.
T36: Apartado 8 (Conclusiones) | U36: 5.1.1 (Investigación) 5.1.5 (Ciclo de vida) | V36: Redacción de conclusiones sobre la viabilidad del proyecto. Reflexión e interpretación de los resultados y reflexión sobre el ciclo de vida del producto en las conclusiones.
T37: Apartado 9 (Referencias bibliográficas) | U37: 5.1.1 (Investigación) 5.3.3 (Ética/responsabilidad herramientas digitales) | V37: Referencias bibliográficas según formato APA. Declaración ética sobre el uso responsable de software, respeto a los derechos de autoría en la red y protección de datos en entornos digitales durante el desarrollo de la investigación
R38: B | S38: Dossier del alumno | U38: 5.1.2 (Participación desarrollo) | V38: Registro de la evolución del diseño. El dossier muestra los bocetos iniciales y la toma de datos. Registro en el Dossier de las modificaciones realizadas desde el boceto inicial hasta el diseño final tras el VºBº. Es la evidencia del trabajo previo a la digitalización.
R39: C | S39: Prueba Escrita (Estructuras/Materiales) | U39: 5.2.1 (Materiales) | V39: Ejercicios de Ingeniería: Resolución presencial de problemas de cálculo de estructuras y propiedades de materiales.
R40: D | S40: Prueba Práctica (Prototipo) | U40: 5.2.2 (Fabricación) | V40: Prueba práctica: El objeto real impreso en 3D. Se evalúa su funcionalidad y la correcta aplicación de las técnicas de taller. Evaluación directa del Prototipo Físico final impreso en 3D y su ensamblaje.
R41: E | S41: G-Code / Archivo Slicer | U41: 5.2.2 (Fabricación) | V41: Configuración óptima del software de laminado (Cura) demostrando autonomía en la resolución de soportes/relleno.
R42: F | S42: Presentación oral | U42: 5.3.2 (Presentación) | V42: Exposición pública del proyecto apoyada en soporte digital (presentación de diapositivas o vídeo). Uso de aplicaciones digitales (Canva, PowerPoint) para realizar la presentación de resultados ante la clase de forma óptima.
R43: G | S43: Tarea de autoevaluación | U43: 5.3.1 (Autonomía) | V43: Reflexión individual sobre el desempeño, la gestión del tiempo y la adquisición de competencias.
R44: H | S44: Tarea de coevaluación | U44: 5.1.6 (Trabajo en equpo y roles) | V44: Aporte al equipo según el rol, escucha activa y fomento del bienestar grupal (evaluado entre pares).
...

Sheet 2ªEV
A1: 2ª EVALUACIÓN
G5: DETALLE | N5: COMPETENCIAS | O5: PORCENTAJE DE NOTA DE LA MATERIA | P5: PONDERACIÓN 2ª EV | Q5: % CONSEGUIDO 2º TRIMESTRE
A6: CRIT EVAL | B6: PONDERACIÓN DEL CURSO | C6: PROGRESO | D6: PONDERACIÓN 2ª EV | E6: CONSEGUIDO | F6: % CONSEGUIDO | G6: EVIDENCIA A | H6: EVIDENCIA B | I6: EVIDENCIA C | J6: EVIDENCIA D | K6: EVIDENCIA E | L6: EVIDENCIA F | N6: CE1 | O6: =1/6 -> 0.16666667 | P6: =D13 -> 0.034722222 | Q6: =F13 -> 0.034722222
A7: 46023 | B7: ='peso de las competencias'!G4 -> 0.027777778 | C7: 0.25 | D7: =C7*B7 -> 0.0069444444 | E7: =IF($C7=0, 0, IFERROR(SUM($G7:$L7)/COUNT($G7:$L7), 0)) -> 10 | F7: =(E7/10)*D7 -> 0.0069444444 | G7: 10 | N7: CE2 | O7: =1/6 -> 0.16666667 | P7: =D21 -> 0.010416667 | Q7: =F21 -> 0.010416667
A8: 46054 | B8: ='peso de las competencias'!G5 -> 0.027777778 | C8: 0.25 | D8: =C8*B8 -> 0.0069444444 | E8: =IF($C8=0, 0, IFERROR(SUM($G8:$L8)/COUNT($G8:$L8), 0)) -> 10 | F8: =(E8/10)*D8 -> 0.0069444444 | G8: 10 | N8: CE3 | O8: =1/6 -> 0.16666667 | P8: =D28 -> 0.027777778 | Q8: =F28 -> 0.027777778
A9: 46082 | B9: ='peso de las competencias'!G6 -> 0.027777778 | C9: 0.25 | D9: =C9*B9 -> 0.0069444444 | E9: =IF($C9=0, 0, IFERROR(SUM($G9:$L9)/COUNT($G9:$L9), 0)) -> 10 | F9: =(E9/10)*D9 -> 0.0069444444 | J9: 10 | L9: 10 | N9: CE4 | O9: =1/6 -> 0.16666667 | P9: =D36 -> 0.083333333 | Q9: =F36 -> 0.083333333
A10: 46113 | B10: ='peso de las competencias'!G7 -> 0.027777778 | C10: 0.25 | D10: =C10*B10 -> 0.0069444444 | E10: =IF($C10=0, 0, IFERROR(SUM($G10:$L10)/COUNT($G10:$L10), 0)) -> 10 | F10: =(E10/10)*D10 -> 0.0069444444 | L10: 10 | N10: CE5 | O10: =1/6 -> 0.16666667 | P10: 0 | Q10: 0
A11: 46143 | B11: ='peso de las competencias'!G8 -> 0.027777778 | C11: 0 | D11: =C11*B11 -> 0 | E11: =IF($C11=0, 0, IFERROR(SUM($G11:$L11)/COUNT($G11:$L11), 0)) -> 0 | F11: =(E11/10)*D11 -> 0 | N11: CE6 | O11: =1/6 -> 0.16666667 | P11: =D44 -> 0.041666667 | Q11: =F44 -> 0.041666667
A12: 46174 | B12: ='peso de las competencias'!G9 -> 0.027777778 | C12: 0.25 | D12: =C12*B12 -> 0.0069444444 | E12: =IF($C12=0, 0, IFERROR(SUM($G12:$L12)/COUNT($G12:$L12), 0)) -> 10 | F12: =(E12/10)*D12 -> 0.0069444444 | H12: 10 | N12: TOTAL | O12: =SUM(O6:O11) -> 1 | P12: =SUM(P6:P11) -> 0.19791667 | Q12: =SUM(Q6:Q11) -> 0.19791667
A13: COMP ESP 1 | B13: =SUM(B7:B12) -> 0.16666667 | D13: =SUM(D7:D12) -> 0.034722222 | F13: =SUM(F7:F12) -> 0.034722222 | O13: 1ª EVALUACIÓN | P13: ='1ªEV'!T12 -> 0.21875 | Q13: ='1ªEV'!U12 -> 0.21875
O14: % TOTAL | P14: =SUM(P12:P13) -> 0.41666667 | Q14: =SUM(Q12:Q13) -> 0.41666667
G15: DETALLE | P15: NOTA 2ª EVALUACIÓN | Q15: =IF(P14=0, 0, (Q14/P14)*10) -> 10
A16: CRIT EVAL | B16: PONDERACIÓN DEL CURSO | C16: PROGRESO | D16: PONDERACIÓN 2ª EV | E16: CONSEGUIDO | F16: % CONSEGUIDO | G16: EVIDENCIA A | H16: EVIDENCIA B | I16: EVIDENCIA C | J16: EVIDENCIA D | K16: EVIDENCIA E | L16: EVIDENCIA F
A17: 46024 | B17: ='peso de las competencias'!G12 -> 0.041666667 | C17: 0 | D17: =C17*B17 -> 0 | E17: =IF($C17=0, 0, IFERROR(SUM($G17:$L17)/COUNT($G17:$L17), 0)) -> 0 | F17: =(E17/10)*D17 -> 0
A18: 46055 | B18: ='peso de las competencias'!G13 -> 0.041666667 | C18: 0.25 | D18: =C18*B18 -> 0.010416667 | E18: =IF($C18=0, 0, IFERROR(SUM($G18:$L18)/COUNT($G18:$L18), 0)) -> 10 | F18: =(E18/10)*D18 -> 0.010416667 | J18: 10
A19: 46083 | B19: ='peso de las competencias'!G14 -> 0.041666667 | C19: 0 | D19: =C19*B19 -> 0 | E19: =IF($C19=0, 0, IFERROR(SUM($G19:$L19)/COUNT($G19:$L19), 0)) -> 0 | F19: =(E19/10)*D19 -> 0
A20: 46114 | B20: ='peso de las competencias'!G15 -> 0.041666667 | C20: 0 | D20: =C20*B20 -> 0 | E20: =IF($C20=0, 0, IFERROR(SUM($G20:$L20)/COUNT($G20:$L20), 0)) -> 0 | F20: =(E20/10)*D20 -> 0
A21: COMP ESP 2 | B21: =SUM(B17:B20) -> 0.16666667 | D21: =SUM(D17:D20) -> 0.010416667 | F21: =SUM(F17:F20) -> 0.010416667
G23: DETALLE
A24: CRIT EVAL | B24: PONDERACIÓN DEL CURSO | C24: PROGRESO | D24: PONDERACIÓN 2ª EV | E24: CONSEGUIDO | F24: % CONSEGUIDO | G24: EVIDENCIA A | H24: EVIDENCIA B | I24: EVIDENCIA C | J24: EVIDENCIA D | K24: EVIDENCIA E | L24: EVIDENCIA F
A25: 46025 | B25: ='peso de las competencias'!G18 -> 0.055555556 | C25: 0.25 | D25: =C25*B25 -> 0.013888889 | E25: =IF($C25=0, 0, IFERROR(SUM($G25:$L25)/COUNT($G25:$L25), 0)) -> 10 | F25: =(E25/10)*D25 -> 0.013888889 | K25: 10
A26: 46056 | B26: ='peso de las competencias'!G19 -> 0.055555556 | C26: 0 | D26: =C26*B26 -> 0 | E26: =IF($C26=0, 0, IFERROR(SUM($G26:$L26)/COUNT($G26:$L26), 0)) -> 0 | F26: =(E26/10)*D26 -> 0 | I26: 10
A27: 46084 | B27: ='peso de las competencias'!G20 -> 0.055555556 | C27: 0.25 | D27: =C27*B27 -> 0.013888889 | E27: =IF($C27=0, 0, IFERROR(SUM($G27:$L27)/COUNT($G27:$L27), 0)) -> 10 | F27: =(E27/10)*D27 -> 0.013888889 | I27: 10
A28: COMP ESP 3 | B28: =SUM(B25:B27) -> 0.16666667 | D28: =SUM(D25:D27) -> 0.027777778 | F28: =SUM(F25:F27) -> 0.027777778
G30: DETALLE
A31: CRIT EVAL | B31: PONDERACIÓN DEL CURSO | C31: PROGRESO | D31: PONDERACIÓN 2ª EV | E31: CONSEGUIDO | F31: % CONSEGUIDO | G31: EVIDENCIA A | H31: EVIDENCIA B | I31: EVIDENCIA C | J31: EVIDENCIA D | K31: EVIDENCIA E | L31: EVIDENCIA F
A32: 46026 | B32: ='peso de las competencias'!G23 -> 0.041666667 | C32: 1 | D32: =C32*B32 -> 0.041666667 | E32: =IF($C32=0, 0, IFERROR(SUM($G32:$L32)/COUNT($G32:$L32), 0)) -> 10 | F32: =(E32/10)*D32 -> 0.041666667 | G32: 10 | K32: 10
A33: 46057 | B33: ='peso de las competencias'!G24 -> 0.041666667 | C33: 0 | D33: =C33*B33 -> 0 | E33: =IF($C33=0, 0, IFERROR(SUM($G33:$L33)/COUNT($G33:$L33), 0)) -> 0 | F33: =(E33/10)*D33 -> 0
A34: 46085 | B34: ='peso de las competencias'!G25 -> 0.041666667 | C34: 0 | D34: =C34*B34 -> 0 | E34: =IF($C34=0, 0, IFERROR(SUM($G34:$L34)/COUNT($G34:$L34), 0)) -> 0 | F34: =(E34/10)*D34 -> 0
A35: 46116 | B35: ='peso de las competencias'!G26 -> 0.041666667 | C35: 1 | D35: =C35*B35 -> 0.041666667 | E35: =IF($C35=0, 0, IFERROR(SUM($G35:$L35)/COUNT($G35:$L35), 0)) -> 10 | F35: =(E35/10)*D35 -> 0.041666667 | K35: 10
A36: COMP ESP 4 | B36: =SUM(B32:B35) -> 0.16666667 | D36: =SUM(D32:D35) -> 0.083333333 | F36: =SUM(F32:F35) -> 0.083333333
G38: DETALLE
A39: CRIT EVAL | B39: PONDERACIÓN DEL CURSO | C39: PROGRESO | D39: PONDERACIÓN 2ª EV | E39: CONSEGUIDO | F39: % CONSEGUIDO | G39: EVIDENCIA A | H39: EVIDENCIA B | I39: EVIDENCIA C | J39: EVIDENCIA D | K39: EVIDENCIA E | L39: EVIDENCIA F
A40: 46028 | B40: ='peso de las competencias'!G36 -> 0.041666667 | C40: 0 | D40: =C40*B40 -> 0 | E40: =IF($C40=0, 0, IFERROR(SUM($G40:$L40)/COUNT($G40:$L40), 0)) -> 0 | F40: =(E40/10)*D40 -> 0
A41: 46059 | B41: ='peso de las competencias'!G37 -> 0.041666667 | C41: 0 | D41: =C41*B41 -> 0 | E41: =IF($C41=0, 0, IFERROR(SUM($G41:$L41)/COUNT($G41:$L41), 0)) -> 0 | F41: =(E41/10)*D41 -> 0
A42: 46087 | B42: ='peso de las competencias'!G38 -> 0.041666667 | C42: 0 | D42: =C42*B42 -> 0 | E42: =IF($C42=0, 0, IFERROR(SUM($G42:$L42)/COUNT($G42:$L42), 0)) -> 0 | F42: =(E42/10)*D42 -> 0
A43: 46118 | B43: ='peso de las competencias'!G39 -> 0.041666667 | C43: 1 | D43: =C43*B43 -> 0.041666667 | E43: =IF($C43=0, 0, IFERROR(SUM($G43:$L43)/COUNT($G43:$L43), 0)) -> 10 | F43: =(E43/10)*D43 -> 0.041666667 | J43: 10
A44: COMP ESP 6 | B44: =SUM(B40:B43) -> 0.16666667 | D44: =SUM(D40:D43) -> 0.041666667 | F44: =SUM(F40:F43) -> 0.041666667 | N44: EVIDENCIAS | O44: TIPOS DE EVIDENCIAS | P44: CEv relacionados | Q44: DESCRIPCIÓN
N45: A | O45: Memoria Técnica del Proyecto Urbano | P45: 5.1.1 5.1.2 5.4.1 | Q45: Documento técnico final por equipos que recopila la investigación previa de soluciones de telecomunicación existentes (5.1.1), el proceso iterativo de diseño y mejora de la torre de telecomunicaciones móvil (5.1.2), y la justificación analítica del cálculo de engranajes, esfuerzos estructurales e integración de sistemas mecánicos (5.4.1).
N46: B | O46: Registro de Taller y Coevaluación de Pares | P46: 5.1.6 | Q46: Matriz de evaluación entre iguales y observación directa en el taller. Mide el desempeño del alumno en el entorno real de trabajo, analizando el cumplimiento de las tareas del rol asignado, el respeto a las opiniones de los demás mediante la escucha activa y su aportación directa al clima de bienestar grupal (5.1.6).
...

Sheet EV FINAL
A1: EVALUACIÓN FINAL
G5: DETALLE | O5: COMPETENCIAS | P5: PORCENTAJE DE NOTA DE LA MATERIA | Q5: PONDERACIÓN 3ª EV | R5: % CONSEGUIDO 3º TRIMESTRE
A6: CRIT EVAL | B6: PONDERACIÓN DEL CURSO | C6: PROGRESO | D6: PONDERACIÓN 3ª EV | E6: CONSEGUIDO | F6: % CONSEGUIDO | G6: EVIDENCIA A | H6: EVIDENCIA B | I6: EVIDENCIA C | J6: EVIDENCIA D | K6: EVIDENCIA E | L6: EVIDENCIA F | M6: EVIDENCIA G | O6: CE1 | P6: =1/6 -> 0.16666667 | Q6: =D13 -> 0.083333333 | R6: =F13 -> 0.041666667
A7: 46023 | B7: ='peso de las competencias'!G4 -> 0.027777778 | C7: 0.5 | D7: =C7*B7 -> 0.013888889 | E7: =IF($C7=0, 0, IFERROR(SUM($G7:$N7)/COUNT($G7:$N7), 0)) -> 0 | F7: =(E7/10)*D7 -> 0 | O7: CE2 | P7: =1/6 -> 0.16666667 | Q7: =D21 -> 0.041666667 | R7: =F21 -> 0.020833333
A8: 46054 | B8: ='peso de las competencias'!G5 -> 0.027777778 | C8: 0.5 | D8: =C8*B8 -> 0.013888889 | E8: =IF($C8=0, 0, IFERROR(SUM($G8:$N8)/COUNT($G8:$N8), 0)) -> 0 | F8: =(E8/10)*D8 -> 0 | O8: CE3 | P8: =1/6 -> 0.16666667 | Q8: =D28 -> 0.083333333 | R8: =F28 -> 0.055555556
A9: 46082 | B9: ='peso de las competencias'!G6 -> 0.027777778 | C9: 0.5 | D9: =C9*B9 -> 0.013888889 | E9: =IF($C9=0, 0, IFERROR(SUM($G9:$N9)/COUNT($G9:$N9), 0)) -> 10 | F9: =(E9/10)*D9 -> 0.013888889 | H9: 10 | O9: CE4 | P9: =1/6 -> 0.16666667 | Q9: 0 | R9: =Q9*P9 -> 0
A10: 46113 | B10: ='peso de las competencias'!G7 -> 0.027777778 | C10: 0.5 | D10: =C10*B10 -> 0.013888889 | E10: =IF($C10=0, 0, IFERROR(SUM($G10:$N10)/COUNT($G10:$N10), 0)) -> 10 | F10: =(E10/10)*D10 -> 0.013888889 | H10: 10 | O10: CE5 | P10: =1/6 -> 0.16666667 | Q10: 0 | R10: =Q10*P10 -> 0
A11: 46143 | B11: ='peso de las competencias'!G8 -> 0.027777778 | C11: 0.5 | D11: =C11*B11 -> 0.013888889 | E11: =IF($C11=0, 0, IFERROR(SUM($G11:$N11)/COUNT($G11:$N11), 0)) -> 0 | F11: =(E11/10)*D11 -> 0 | O11: CE6 | P11: =1/6 -> 0.16666667 | Q11: 0 | R11: =Q11*P11 -> 0
A12: 46174 | B12: ='peso de las competencias'!G9 -> 0.027777778 | C12: 0.5 | D12: =C12*B12 -> 0.013888889 | E12: =IF($C12=0, 0, IFERROR(SUM($G12:$N12)/COUNT($G12:$N12), 0)) -> 10 | F12: =(E12/10)*D12 -> 0.013888889 | I12: 10 | O12: TOTAL | P12: =SUM(P6:P11) -> 1 | Q12: =SUM(Q6:Q11) -> 0.20833333 | R12: =SUM(R6:R11) -> 0.11805556
A13: COMP ESP 1 | B13: =SUM(B7:B12) -> 0.16666667 | D13: =SUM(D7:D12) -> 0.083333333 | F13: =SUM(F7:F12) -> 0.041666667 | P13: 2ª EVALUACIÓN | Q13: ='2ªEV'!P14 -> 0.41666667 | R13: ='2ªEV'!Q14 -> 0.41666667
P14: % TOTAL | Q14: =SUM(Q12:Q13) -> 0.625 | R14: =SUM(R12:R13) -> 0.53472222
G15: DETALLE | Q15: NOTA 2ª EVALUACIÓN | R15: =IF(Q14=0, 0, (R14/Q14)*10) -> 8.5555556
A16: CRIT EVAL | B16: PONDERACIÓN DEL CURSO | C16: PROGRESO | D16: PONDERACIÓN 3ª EV | E16: CONSEGUIDO | F16: % CONSEGUIDO | G16: EVIDENCIA A | H16: EVIDENCIA B | I16: EVIDENCIA C | J16: EVIDENCIA D | K16: EVIDENCIA E | L16: EVIDENCIA F | M16: EVIDENCIA G
A17: 46024 | B17: ='peso de las competencias'!G12 -> 0.041666667 | C17: 0 | D17: =C17*B17 -> 0 | E17: =IF($C17=0, 0, IFERROR(SUM($G17:$N17)/COUNT($G17:$N17), 0)) -> 0 | F17: =(E17/10)*D17 -> 0 | G17: 10
A18: 46055 | B18: ='peso de las competencias'!G13 -> 0.041666667 | C18: 0.5 | D18: =C18*B18 -> 0.020833333 | E18: =IF($C18=0, 0, IFERROR(SUM($G18:$N18)/COUNT($G18:$N18), 0)) -> 10 | F18: =(E18/10)*D18 -> 0.020833333 | G18: 10 | K18: 10
A19: 46083 | B19: ='peso de las competencias'!G14 -> 0.041666667 | C19: 0 | D19: =C19*B19 -> 0 | E19: =IF($C19=0, 0, IFERROR(SUM($G19:$N19)/COUNT($G19:$N19), 0)) -> 0 | F19: =(E19/10)*D19 -> 0
A20: 46114 | B20: ='peso de las competencias'!G15 -> 0.041666667 | C20: 0.5 | D20: =C20*B20 -> 0.020833333 | E20: =IF($C20=0, 0, IFERROR(SUM($G20:$N20)/COUNT($G20:$N20), 0)) -> 0 | F20: =(E20/10)*D20 -> 0
A21: COMP ESP 2 | B21: =SUM(B17:B20) -> 0.16666667 | D21: =SUM(D17:D20) -> 0.041666667 | F21: =SUM(F17:F20) -> 0.020833333
G23: DETALLE
A24: CRIT EVAL | B24: PONDERACIÓN DEL CURSO | C24: PROGRESO | D24: PONDERACIÓN 3ª EV | E24: CONSEGUIDO | F24: % CONSEGUIDO | G24: EVIDENCIA A | H24: EVIDENCIA B | I24: EVIDENCIA C | J24: EVIDENCIA D | K24: EVIDENCIA E | L24: EVIDENCIA F | M24: EVIDENCIA G
A25: 46025 | B25: ='peso de las competencias'!G18 -> 0.055555556 | C25: 0.5 | D25: =C25*B25 -> 0.027777778 | E25: =IF($C25=0, 0, IFERROR(SUM($G25:$N25)/COUNT($G25:$N25), 0)) -> 10 | F25: =(E25/10)*D25 -> 0.027777778 | M25: 10
A26: 46056 | B26: ='peso de las competencias'!G19 -> 0.055555556 | C26: 0.5 | D26: =C26*B26 -> 0.027777778 | E26: =IF($C26=0, 0, IFERROR(SUM($G26:$N26)/COUNT($G26:$N26), 0)) -> 0 | F26: =(E26/10)*D26 -> 0
A27: 46084 | B27: ='peso de las competencias'!G20 -> 0.055555556 | C27: 0.5 | D27: =C27*B27 -> 0.027777778 | E27: =IF($C27=0, 0, IFERROR(SUM($G27:$N27)/COUNT($G27:$N27), 0)) -> 10 | F27: =(E27/10)*D27 -> 0.027777778 | J27: 10
A28: COMP ESP 3 | B28: =SUM(B25:B27) -> 0.16666667 | D28: =SUM(D25:D27) -> 0.083333333 | F28: =SUM(F25:F27) -> 0.055555556
G30: DETALLE
A31: CRIT EVAL | B31: PONDERACIÓN DEL CURSO | C31: PROGRESO | D31: PONDERACIÓN 3ª EV | E31: CONSEGUIDO | F31: % CONSEGUIDO | G31: EVIDENCIA A | H31: EVIDENCIA B | I31: EVIDENCIA C | J31: EVIDENCIA D | K31: EVIDENCIA E | L31: EVIDENCIA F | M31: EVIDENCIA G
A32: 46026 | B32: ='peso de las competencias'!G23 -> 0.041666667 | C32: 0 | D32: =C32*B32 -> 0 | E32: =IF($C32=0, 0, IFERROR(SUM($G32:$N32)/COUNT($G32:$N32), 0)) -> 0 | F32: =(E32/10)*D32 -> 0
A33: 46057 | B33: ='peso de las competencias'!G24 -> 0.041666667 | C33: 1 | D33: =C33*B33 -> 0.041666667 | E33: =IF($C33=0, 0, IFERROR(SUM($G33:$N33)/COUNT($G33:$N33), 0)) -> 10 | F33: =(E33/10)*D33 -> 0.041666667 | G33: 10
A34: 46085 | B34: ='peso de las competencias'!G25 -> 0.041666667 | C34: 1 | D34: =C34*B34 -> 0.041666667 | E34: =IF($C34=0, 0, IFERROR(SUM($G34:$N34)/COUNT($G34:$N34), 0)) -> 0 | F34: =(E34/10)*D34 -> 0
A35: 46116 | B35: ='peso de las competencias'!G26 -> 0.041666667 | C35: 0 | D35: =C35*B35 -> 0 | E35: =IF($C35=0, 0, IFERROR(SUM($G35:$N35)/COUNT($G35:$N35), 0)) -> 0 | F35: =(E35/10)*D35 -> 0
A36: COMP ESP 4 | B36: =SUM(B32:B35) -> 0.16666667 | D36: =SUM(D32:D35) -> 0.083333333 | F36: =SUM(F32:F35) -> 0.041666667
G38: DETALLE
A39: CRIT EVAL | B39: PONDERACIÓN DEL CURSO | C39: PROGRESO | D39: PONDERACIÓN 3ª EV | E39: CONSEGUIDO | F39: % CONSEGUIDO | G39: EVIDENCIA A | H39: EVIDENCIA B | I39: EVIDENCIA C | J39: EVIDENCIA D | K39: EVIDENCIA E | L39: EVIDENCIA F | M39: EVIDENCIA G
A40: 46027 | B40: ='peso de las competencias'!G29 -> 0.033333333 | C40: 1 | D40: =C40*B40 -> 0.033333333 | E40: =IF($C40=0, 0, IFERROR(SUM($G40:$N40)/COUNT($G40:$N40), 0)) -> 10 | F40: =(E40/10)*D40 -> 0.033333333 | L40: 10
A41: 46058 | B41: ='peso de las competencias'!G30 -> 0.033333333 | C41: 1 | D41: =C41*B41 -> 0.033333333 | E41: =IF($C41=0, 0, IFERROR(SUM($G41:$N41)/COUNT($G41:$N41), 0)) -> 10 | F41: =(E41/10)*D41 -> 0.033333333 | L41: 10 | M41: 10
A42: 46086 | B42: ='peso de las competencias'!G31 -> 0.033333333 | C42: 1 | D42: =C42*B42 -> 0.033333333 | E42: =IF($C42=0, 0, IFERROR(SUM($G42:$N42)/COUNT($G42:$N42), 0)) -> 10 | F42: =(E42/10)*D42 -> 0.033333333 | L42: 10
A43: 46117 | B43: ='peso de las competencias'!G32 -> 0.033333333 | C43: 1 | D43: =C43*B43 -> 0.033333333 | E43: =IF($C43=0, 0, IFERROR(SUM($G43:$N43)/COUNT($G43:$N43), 0)) -> 10 | F43: =(E43/10)*D43 -> 0.033333333 | L43: 10
A44: 46147 | B44: ='peso de las competencias'!G33 -> 0.033333333 | C44: 1 | D44: =C44*B44 -> 0.033333333 | E44: =IF($C44=0, 0, IFERROR(SUM($G44:$N44)/COUNT($G44:$N44), 0)) -> 10 | F44: =(E44/10)*D44 -> 0.033333333 | L44: 10
A45: COMP ESP 5 | B45: =SUM(B40:B44) -> 0.16666667 | D45: =SUM(D40:D44) -> 0.16666667 | F45: =SUM(F40:F44) -> 0.16666667
G47: DETALLE
...
